Workbook
Name Cash_Sweep: LBO!#REF!
Name Circularity: LBO!$G$21
Name IQ_CH: 110000
Name IQ_CQ: 5000
Name IQ_CY: 10000
Name IQ_DAILY: 500000
Name IQ_FH: 100000
Name IQ_FQ: 500
Name IQ_FY: 1000
Name IQ_LTM: 2000
Name IQ_MONTH: 15000
Name IQ_NTM: 6000
Name IQ_WEEK: 50000
Name IQ_YTD: 3000

Sheet LDN
B5: Calculation | C5: Black
B6: Input | C6: Blue
B9: Company Financials (£m) | C9: 45657 | D9: 46022 | E9: 46387 | F9: 46752 | G9: 47118 | H9: 47483
B10: Revenue | C10: 9.99 | D10: 15.7 | E10: 19 | F10: 22.7 | G10: 27.3 | H10: 32.7
B11: EBITDA | C11: 1.034 | D11: 2.312 | E11: 2.377 | F11: 2.961 | G11: 3.762 | H11: 4.743
B14: Current Shareholdings (Diluted) | F14: Other assumptions
F15: Tax | H15: 0.2
B16: Chairman | C16: 521805.28 | D16: 0.331 | F16: CAPEX | H16: 0.01
B17: CEO | C17: 553334.3 | D17: 0.351 | F17: Working capital | H17: 0.1
B18: Sales Director | C18: 102469.32 | D18: 0.065 | F18: Yield on senior debt | H18: 0.05
B19: Operations Director | C19: 95000.025 | D19: 0.060261958 | F19: Deal fees | H19: 0.015
B20: Head of US | C20: 0 | D20: 0 | F20: Cash at Bank | H20: 2.3
B21: External shareholders | C21: 165000.04 | D21: 0.10466551
B22: Employees | C22: 97999.025 | D22: 0.062164333
B23: Option holders | C23: 40843.011 | D23: 0.025908202
C24: 1576451 | D24: 1

Sheet Valuation Summary
A1: Valuation Comparison
B5: LBO Implied EV/EBITDA | C5: =LBO!H8 -> 8.2179931 | D5: (Entry Multiple)
B6: DCF Exit Multiple | C6: =DCF!C6 -> 8.2179931 | D6: =DCF!G58 -> 6.4557875 | E6: (Implied EV/EBITDA)
B7: Public Comps | C7: ='Public Comps'!L27 -> 8.37
B8: Precedent Transactions | C8: ='Precedent Transactions'!J23 -> 10.83
B10: Median | C10: =MEDIAN(C5:C8) -> 8.2939965
B14: Note: Median used for Public Comps, Lower Quartile used for Precedent Transactions

Sheet LBO
B1: Visante - LBO Model
A3: X | B3: Assumptions
B5: Inputs | F5: Valuation related | J5: Transaction Timings
B6: Calculation | C6: Black | F6: Entry EBITDA | H6: 2.312 | J6: Financial Year-end | M6: 46022
B7: Input | C7: Blue | F7: Entry Enterprise Value | H7: 19 | J7: Targeted Completion Date | M7: 45930
F8: Implied Multiple | H8: =H7/H6 -> 8.2179931 | J8: Year Fraction | M8: =(M6-M7)/365 -> 0.25205479
B9: Operating related | F9: EV | H9: =H7 -> 19
B10: Tax | D10: 0.2 | F10: Net cash/ (debt) | H10: 2.3
B11: CAPEX | D11: 0.01 | F11: Working Capital Adj. | H11: 0 | I11: << At this stage, assumed to be no adjustment
B12: Working capital | D12: 0.1 | F12: EqV | H12: =H7+H10 -> 21.3
B13: Yield on senior debt | D13: 0.05
B14: Cash at Bank (£m) | D14: 2.3 | F14: Debt related | H14: Yield | I14: Split | J14: Maturity
B15: FY30 Revenue Growth | D15: 0.2 | F15: TLA - Ammortising | H15: 0.04 | I15: 0.5 | J15: 7
B16: FY30 EBITDA Margin | D16: 0.14 | F16: TLB - Bullet | H16: 0.06 | I16: 0.5 | J16: 7
N17: `
B18: Transaction related | F18: Debt Raised (£m) | H18: 5
B19: Deal fees | D19: 0.015
B20: Completion Consideration | D20: 13
B21: Buyside Fees and Expenses (£m) | D21: 0.555 | F21: Cirularity | G21: Yes
B22: Sweet Equity | D22: 0.25
B23: Pref/ Loan Notes | D23: 0.9
B24: Ordinary Equity | D24: =1-D23 -> 0.1
B25: Loan Note rate | D25: 0.1 | E25: << Assumed PIK
A27: X | B27: Cap Table
B29: Shareholder/ Stakeholder | C29: # Shares | D29: % Holding | E29: Gross Proceeds | F29: Sellers' Fees | G29: Rollover | H29: Rolled Ownership % | I29: Rollover (£m) | J29: Cashout | K29: New capital | L29: NewCo Capital | M29: NewCo LN (£m) | N29: NewCo Equity (£m)
B31: Non Participating
B32: Chairman | C32: 521805.28 | D32: 0.331 | E32: =$H$12*1000000*D32 -> 7050300 | F32: =E32*$D$19 -> 105754.5 | G32: 0 | H32: =D32*G32 -> 0 | I32: =E32*H32 -> 0 | J32: =E32-I32-F32 -> 6944545.5 | K32: =I32 -> 0 | L32: =K32 -> 0 | M32: =L32*$D$23 -> 0 | N32: =L32*$D$24 -> 0
B33: Head of US | C33: 0 | D33: 0 | E33: =$H$12*1000000*D33 -> 0 | F33: =E33*$D$19 -> 0 | G33: 0 | H33: =D33*G33 -> 0 | I33: =E33*H33 -> 0 | J33: =E33-I33-F33 -> 0 | K33: =I33 -> 0 | L33: =K33 -> 0 | M33: =L33*$D$23 -> 0 | N33: =L33*$D$24 -> 0
B34: External shareholders | C34: 165000.04 | D34: 0.10466551 | E34: =$H$12*1000000*D34 -> 2229375.3 | F34: =E34*$D$19 -> 33440.629 | G34: 0 | H34: =D34*G34 -> 0 | I34: =E34*H34 -> 0 | J34: =E34-I34-F34 -> 2195934.7 | K34: =I34 -> 0 | L34: =K34 -> 0 | M34: =L34*$D$23 -> 0 | N34: =L34*$D$24 -> 0
F35: =E35*$D$19 -> 0 | K35: =I35 -> 0
B36: Visante Management | F36: =E36*$D$19 -> 0 | K36: =I36 -> 0
B37: CEO | C37: 553334.3 | D37: 0.351 | E37: =$H$12*1000000*D37 -> 7476300 | F37: =E37*$D$19 -> 112144.5 | G37: 0.5 | H37: =D37*G37 -> 0.1755 | I37: =E37*H37 -> 1312090.6 | J37: =E37-I37-F37 -> 6052064.8 | K37: 0 | L37: =I37+K37 -> 1312090.6 | M37: =L37*$D$23 -> 1180881.6 | N37: =L37*$D$24 -> 131209.07
B38: Sales Director | C38: 102469.32 | D38: 0.065 | E38: =$H$12*1000000*D38 -> 1384500 | F38: =E38*$D$19 -> 20767.5 | G38: 0.5 | H38: =D38*G38 -> 0.0325 | I38: =E38*H38 -> 44996.25 | J38: =E38-I38-F38 -> 1318736.2 | K38: 0 | L38: =I38+K38 -> 44996.25 | M38: =L38*$D$23 -> 40496.625 | N38: =L38*$D$24 -> 4499.625
B39: Operations Director | C39: 95000.025 | D39: 0.060261958 | E39: =$H$12*1000000*D39 -> 1283579.7 | F39: =E39*$D$19 -> 19253.696 | G39: 0.5 | H39: =D39*G39 -> 0.030130979 | I39: =E39*H39 -> 38675.514 | J39: =E39-I39-F39 -> 1225650.5 | K39: 0 | L39: =I39+K39 -> 38675.514 | M39: =L39*$D$23 -> 34807.962 | N39: =L39*$D$24 -> 3867.5514
F40: =E40*$D$19 -> 0
B41: Visante Employees | F41: =E41*$D$19 -> 0
B42: Employees | C42: 97999.025 | D42: 0.062164333 | E42: =$H$12*1000000*D42 -> 1324100.3 | F42: =E42*$D$19 -> 19861.504 | G42: 0.5 | H42: =D42*G42 -> 0.031082167 | I42: =E42*H42 -> 41155.906 | J42: =E42-I42-F42 -> 1263082.9 | K42: 0 | L42: =I42+K42 -> 41155.906 | M42: =L42*$D$23 -> 37040.315 | N42: =L42*$D$24 -> 4115.5906
B43: Existing Option holders | C43: 40843.011 | D43: 0.025908202 | E43: =$H$12*1000000*D43 -> 551844.7 | F43: =E43*$D$19 -> 8277.6705 | G43: 0.5 | H43: =D43*G43 -> 0.012954101 | I43: =E43*H43 -> 7148.6519 | J43: =E43-I43-F43 -> 536418.37 | K43: 0 | L43: =I43+K43 -> 7148.6519 | M43: =L43*$D$23 -> 6433.7867 | N43: =L43*$D$24 -> 714.86519
B45: New Capital
B46: XPE | C46: 0 | D46: 0 | E46: =C46*D46 -> 0 | F46: =E46*0.015 -> 0 | G46: 0 | H46: =D46*G46 -> 0 | I46: =E46*H46 -> 0 | J46: =E46-I46-F46 -> 0 | K46: =($D$20+$D$14+$D$21-$H$18-2*$D$14*$H$50)*1000000 -> 9557030.7 | L46: =K46 -> 9557030.7 | M46: =L46*$D$23 -> 8601327.6 | N46: =L46*$D$24 -> 955703.07
...

Sheet DCF
B1: Visante - DCF Model
A3: x | B3: Assumptions
B5: Perpetuity Growth | C5: 0.02 | E5: Calculation | F5: Black | G5: Completion | I5: 45930
B6: Exit Multiple | C6: =LBO!H8 -> 8.2179931 | E6: Input | F6: Blue | G6: Financial Year-end | I6: 46022
B7: Tax Rate | C7: 0.2 | G7: Year Fraction | I7: 0.25
B8: Long-term Debt/Equity | C8: 0.5
A11: x | B11: WACC
B13: Cost of Debt | C13: =(LBO!D70*LBO!H15+LBO!D71*LBO!H16)/LBO!H18 -> 0.05
B14: Debt | C14: =LBO!J123+LBO!J129 -> 3.1242661 | K14: Beta
K15: Computer services | N15: 0.98
B16: Risk Free Rate | C16: 0.044 | K16: Business and consumer services | N16: 0.85
B17: Equity Risk Premium | C17: 0.0513 | K17: Information Services | N17: 0.82
B18: Unlevered Beta | C18: =AVERAGE(N15:N17) -> 0.88333333 | K18: Average | N18: 0.88333333
B19: Levered Beta | C19: =C18*(1+(1-LBO!D10)*C8) -> 1.2366667
B20: Cost of Equity | C20: =C16+C19*C17+C25 -> 0.107441
B21: Equity | C21: =LBO!I153 -> 6609095
B23: Debt + Equity | C23: =C14+C21 -> 6609098.1
B25: Size Premium | C25: 0
B27: WACC | C27: =C20*C21/C23+C13*(1-LBO!D10)*C14/C23 -> 0.10744097
A30: x | B30: DCF
C32: 46022 | D32: Q425F | E32: 46387 | F32: 46752 | G32: 47118 | H32: 47483 | I32: 47848
B34: Revenue | C34: =LBO!D95 -> 15.7 | D34: =LBO!E95 -> 3.9572603 | E34: =LBO!F95 -> 19 | F34: =LBO!G95 -> 22.7 | G34: =LBO!H95 -> 27.3 | H34: =LBO!I95 -> 32.7 | I34: =LBO!J95 -> 39.24
B35: Growth
B36: EBITDA | C36: =LBO!D97 -> 2.312 | D36: =LBO!E97 -> 0.58275068 | E36: =LBO!F97 -> 2.377 | F36: =LBO!G97 -> 2.961 | G36: =LBO!H97 -> 3.762 | H36: =LBO!I97 -> 4.743 | I36: =LBO!J97 -> 5.4936
B37: Less D&A | C37: =LBO!D99 -> -0.157 | D37: =LBO!E99 -> -0.039572603 | E37: =LBO!F99 -> -0.19 | F37: =LBO!G99 -> -0.227 | G37: =LBO!H99 -> -0.273 | H37: =LBO!I99 -> -0.327 | I37: =LBO!J99 -> -0.3924
B38: EBIT | C38: =C36+C37 -> 2.155 | D38: =D36+D37 -> 0.54317808 | E38: =E36+E37 -> 2.187 | F38: =F36+F37 -> 2.734 | G38: =G36+G37 -> 3.489 | H38: =H36+H37 -> 4.416 | I38: =I36+I37 -> 5.1012
B39: Less: Taxes | C39: =-MAX(C38,0)*LBO!$D$10 -> -0.431 | D39: =-MAX(D38,0)*LBO!$D$10 -> -0.10863562 | E39: =-MAX(E38,0)*LBO!$D$10 -> -0.4374 | F39: =-MAX(F38,0)*LBO!$D$10 -> -0.5468 | G39: =-MAX(G38,0)*LBO!$D$10 -> -0.6978 | H39: =-MAX(H38,0)*LBO!$D$10 -> -0.8832 | I39: =-MAX(I38,0)*LBO!$D$10 -> -1.02024
B40: Plus: D&A | C40: =-C37 -> 0.157 | D40: =-D37 -> 0.039572603 | E40: =-E37 -> 0.19 | F40: =-F37 -> 0.227 | G40: =-G37 -> 0.273 | H40: =-H37 -> 0.327 | I40: =-I37 -> 0.3924
B41: Less: CapEx | C41: =LBO!D109 -> -0.157 | D41: =LBO!E109 -> -0.039572603 | E41: =LBO!F109 -> -0.19 | F41: =LBO!G109 -> -0.227 | G41: =LBO!H109 -> -0.273 | H41: =LBO!I109 -> -0.327 | I41: =LBO!J109 -> -0.3924
B42: Less: Increase in NWC | C42: =LBO!D110 -> 0 | D42: =LBO!E110 -> -0.14392329 | E42: =LBO!F110 -> -0.33 | F42: =LBO!G110 -> -0.37 | G42: =LBO!H110 -> -0.46 | H42: =LBO!I110 -> -0.54 | I42: =LBO!J110 -> -0.654
B43: Free Cash Fl ow (FCF) | C43: =C38+C39+C40+C41+C42 -> 1.724 | D43: =D38+D39+D40+D41+D42 -> 0.29061918 | E43: =E38+E39+E40+E41+E42 -> 1.4196 | F43: =F38+F39+F40+F41+F42 -> 1.8172 | G43: =G38+G39+G40+G41+G42 -> 2.3312 | H43: =H38+H39+H40+H41+H42 -> 2.9928 | I43: =I38+I39+I40+I41+I42 -> 3.42696
B45: Period | D45: 0.125 | E45: =D45+1 -> 1.125 | F45: =E45+1 -> 2.125 | G45: =F45+1 -> 3.125 | H45: =G45+1 -> 4.125 | I45: =H45+1 -> 5.125
B46: Discount Factor | D46: =1/(1+$C$27)^D45 -> 0.98732453 | E46: =1/(1+$C$27)^E45 -> 0.89153694 | F46: =1/(1+$C$27)^F45 -> 0.8050424 | G46: =1/(1+$C$27)^G45 -> 0.72693934 | H46: =1/(1+$C$27)^H45 -> 0.65641362 | I46: =1/(1+$C$27)^I45 -> 0.59273012
B48: PV of FCF | D48: =D43*D46 -> 0.28693544 | E48: =E43*E46 -> 1.2656258 | F48: =F43*F46 -> 1.4629231 | G48: =G43*G46 -> 1.694641 | H48: =H43*H46 -> 1.9645147 | I48: =I43*I46 -> 2.0312624
B49: Sum of PV of FCF | I49: =SUM(D48:I48) -> 8.7059024
B52: Enterprise Value - PGM | E52: Enterprise Value - EMM
B53: Terminal Value | C53: =I43*(1+C5)/(C27-C5) -> 39.975532 | E53: Terminal Value | G53: =I36*C6 -> 45.146367
B54: PV of Terminal Value | C54: =C53*I46 -> 23.694702 | E54: PV of Terminal Value | G54: =G53*I46 -> 26.759612
B55: Cumulative FCF | C55: =I49 -> 8.7059024 | E55: Cumulative FCF | G55: =I49 -> 8.7059024
B56: Enterprise Value | C56: =C54+C55 -> 32.400604 | E56: Enterprise Value | G56: =G54+G55 -> 35.465514
...

Sheet Public Comps
B2: Visante - Public Comparibles
B4: Calculation | C4: Black
B5: Input | C5: Blue
K7: Valuation Metrics
C8: Price (£) | D8: Shares | E8: Market | F8: Total | G8: Total | H8: Enterprise | I8: Revenue | J8: EBITDA | K8: Revenue | L8: EBITDA | M8: Location | N8: Description
B9: Company | D9: Oustanding (m) | E9: Cap (£m) | F9: Cash | G9: Debt | H9: Value | I9: LYE | J9: LYE | K9: LYE | L9: LYE
B11: Bytes Technology Group plc | C11: 3.722 | D11: 237.62 | E11: =C11*D11 -> 884.42164 | F11: 113 | G11: 1.94 | H11: =E11-F11+G11 -> 773.36164 | I11: 217 | J11: 68.64 | K11: =IF(I11>0,H11/I11,"-") -> 3.5638785 | L11: =IF(J11<>"",H11/J11,"-") -> 11.266924 | M11: UK | N11: IT software and hardware distributor with strong managed services, security, and cloud solutions for business customers.
B12: Computacenter plc | C12: 28.46 | D12: 106.24 | E12: =C12*D12 -> 3023.5904 | F12: 489.6 | G12: 136.9 | H12: =E12-F12+G12 -> 2670.8904 | I12: 6965 | J12: 237 | K12: =IF(I12>0,H12/I12,"-") -> 0.38347314 | L12: =IF(J12<>"",H12/J12,"-") -> 11.26958 | M12: UK | N12: Provides IT infrastructure, supply chain management, managed services, and consulting to large organizations.
B13: FDM Group (Holdings) plc | C13: 1.2263 | D13: 109.72 | E13: =C13*D13 -> 134.54964 | F13: 41 | G13: 22 | H13: =E13-F13+G13 -> 115.54964 | I13: 258 | J13: 27 | K13: =IF(I13>0,H13/I13,"-") -> 0.44786681 | L13: =IF(J13<>"",H13/J13,"-") -> 4.2796161 | M13: UK | N13: Graduate recruitment, IT skills training, and staff augmentation—places consultants with clients on long-term contracts.
B14: Softcat plc | C14: 15.8 | D14: 199.95 | E14: =C14*D14 -> 3159.21 | F14: 182 | G14: 0 | H14: =E14-F14+G14 -> 2977.21 | I14: 1458 | J14: 173.21 | K14: =IF(I14>0,H14/I14,"-") -> 2.0419822 | L14: =IF(J14<>"",H14/J14,"-") -> 17.188442 | M14: UK | N14: IT infrastructure reseller with managed services, security, cloud, and software licensing overlays.
B15: TPXimpact Holdings plc | C15: 0.14 | D15: 92.97 | E15: =C15*D15 -> 13.0158 | F15: 4.65 | G15: 14 | H15: =E15-F15+G15 -> 22.3658 | I15: 77 | J15: -2.36 | K15: =IF(I15>0,H15/I15,"-") -> 0.29046494 | L15: =IF(J15<>"",H15/J15,"-") -> -9.4770339 | M15: UK | N15: Digital consulting for the UK public sector, focusing on cloud, transformation, and gov.uk project delivery.
B16: Kainos Group plc | C16: 9.38 | D16: 119.23 | E16: =C16*D16 -> 1118.3774 | F16: 134 | G16: 5.56 | H16: =E16-F16+G16 -> 989.9374 | I16: 367 | J16: 43 | K16: =IF(I16>0,H16/I16,"-") -> 2.6973771 | L16: =IF(J16<>"",H16/J16,"-") -> 23.0218 | M16: UK | N16: Kainos Group plc is a United Kingdom-based information technology (IT) provider. The Company operates through three divisions, including Digital Services, Workday Services, and Workday Products.
B17: Cerillion plc | C17: 14.03 | D17: 29.5 | E17: =C17*D17 -> 413.885 | F17: 30 | G17: 2.8 | H17: =E17-F17+G17 -> 386.685 | I17: 44 | J17: 18 | K17: =IF(I17>0,H17/I17,"-") -> 8.7882955 | L17: =IF(J17<>"",H17/J17,"-") -> 21.4825 | M17: UK | N17: Cerillion plc is a United Kingdom-based software solutions provider for billing, charging and customer relationship management (CRM).
B18: dotdigital Group plc | C18: 0.7092 | D18: 307.8 | E18: =C18*D18 -> 218.29176 | F18: 36 | G18: 1.78 | H18: =E18-F18+G18 -> 184.07176 | I18: 79 | J18: 22 | K18: =IF(I18>0,H18/I18,"-") -> 2.3300223 | L18: =IF(J18<>"",H18/J18,"-") -> 8.3668982 | M18: UK | N18: Dotdigital Group plc is a United Kingdom-based software-as-a-service (SaaS) provider of an all-in-one customer experience and data platform (CXDP).
B19: Idox plc | C19: 0.7075 | D19: 461.68 | E19: =C19*D19 -> 326.6386 | F19: 12 | G19: 24 | H19: =E19-F19+G19 -> 338.6386 | I19: 88 | J19: 22 | K19: =IF(I19>0,H19/I19,"-") -> 3.8481659 | L19: =IF(J19<>"",H19/J19,"-") -> 15.392664 | M19: UK | N19: Idox plc is a supplier of specialist information management software and geospatial data solutions to the public and asset-intensive sectors.
B20: Gamma Communications plc | C20: 9.66 | D20: 92.17 | E20: =C20*D20 -> 890.3622 | F20: 154 | G20: 7.9 | H20: =E20-F20+G20 -> 744.2622 | I20: 579 | J20: 124 | K20: =IF(I20>0,H20/I20,"-") -> 1.2854269 | L20: =IF(J20<>"",H20/J20,"-") -> 6.0021145 | M20: UK | N20: A UK-based provider of unified communications as a service (UCaaS), telecom, and connectivity solutions. Serving SMEs, large enterprises, and public sector across Europe, Gamma delivers telephony, mobile, broadband, cloud, and collaboration products over its own network infrastructure
B21: Team Internet Group plc | C21: 0.4629 | D21: 246.18 | E21: =C21*D21 -> 113.95672 | F21: 88 | G21: 189 | H21: =E21-F21+G21 -> 214.95672 | I21: 803 | J21: 50.2 | K21: =IF(I21>0,H21/I21,"-") -> 0.26769206 | L21: =IF(J21<>"",H21/J21,"-") -> 4.2820064 | M21: UK | N21: Formerly CentralNic Group plc, this is a British multinational internet services company. It operates in two main segments: Online Marketing (generating digital advertising and traffic monetization revenue) and Online Presence (providing domain registration, management, and associated services globally).
B22: Datrix Group plc | C22: 1.463788 | D22: 9.81 | E22: =C22*D22 -> 14.35976 | F22: 5.572976 | G22: 4.303184 | H22: =E22-F22+G22 -> 13.089968 | I22: 15.8724 | J22: 20.669392 | K22: =IF(I22>0,H22/I22,"-") -> 0.8247 | L22: =IF(J22<>"",H22/J22,"-") -> 0.63330205 | M22: Italy | N22: Datrix SpA is an Italy-based company that provides augmented analytics software and service solutions based on proprietary artificial intelligence (AI) technologies for marketing, sales, publishing and finance purposes.
... B24: Atos SE | C24: 43.499194 | D24: 19.38 | E24: =C24*D24 -> 843.01438 | F24: 1533.4502 | G24: 2478.7398 | H24: =E24-F24+G24 -> 1788.304 | I24: 8444.9986 | J24: 2478.7398 | K24: =IF(I24>0,H24/I24,"-") -> 0.21175894 | L24: =IF(J24<>"",H24/J24,"-") -> 0.72145692 | M24: France | N24: Multinational IT services and consulting specializing in digital transformation, cloud, cybersecurity, and HPC.
B26: 25th Percentile | K26: 0.4 | L26: 4.28
B27: Median | K27: 1.06 | L27: 8.37
B28: 75th Percentile | K28: 2.61 | L28: 15.39
B30: Exchange rate used (Eur/GBP) | C30: 0.8818
B31: Financial Data from Financial Times
B32: Cash, debt, revenue and EBITDA based on latest Year-end information available

Sheet Precedent Transactions
B1: Visante - Precedent Transactions
B3: Year | C3: Target Name | D3: Country | E3: Acquirer | F3: Deal Value (£m) | G3: Target Revenue (£m) | H3: Target EBITDA (£m) | I3: EV/Revenue Multiple | J3: EV/EBITDA Multiple | K3: Business Focus
B4: 2025 | C4: Oakland Group Services | D4: UK | E4: Softcat plc | F4: 8 | G4: 10 | H4: 1.8 | I4: =IF(ISNUMBER(F4),F4/G4,"Undisclosed") -> 0.8 | J4: =IF(AND(ISNUMBER(F4),ISNUMBER(H4)),F4/H4,"Undisclosed") -> 4.4444444 | K4: Data & AI strategy consulting
B5: 2025 | C5: Fox Crypto | D5: UK | E5: CR Group Nordic AB | F5: 65.6 | G5: 23 | H5: 4 | I5: =IF(ISNUMBER(F5),F5/G5,"Undisclosed") -> 2.8521739 | J5: =IF(AND(ISNUMBER(F5),ISNUMBER(H5)),F5/H5,"Undisclosed") -> 16.4 | K5: Cryptographic products
B6: 2020 | C6: Context Information Security | D6: UK | E6: Accenture plc | F6: 107 | G6: 60 | H6: 2 | I6: =IF(ISNUMBER(F6),F6/G6,"Undisclosed") -> 1.7833333 | J6: =IF(AND(ISNUMBER(F6),ISNUMBER(H6)),F6/H6,"Undisclosed") -> 53.5 | K6: Cybersecurity consulting
B7: 2024 | C7: Elastacloud | D7: UK | E7: Acora | F7: Undisclosed | G7: Small | H7: Undisclosed | I7: =IF(ISNUMBER(F7),F7/G7,"Undisclosed") -> Undisclosed | J7: =IF(AND(ISNUMBER(F7),ISNUMBER(H7)),F7/H7,"Undisclosed") -> Undisclosed | K7: Data science & AI (Microsoft Azure)
B8: 2025 | C8: Risk Crew | D8: UK | E8: Red Helix (LDC-backed) | F8: Undisclosed | G8: Small | H8: Undisclosed | I8: =IF(ISNUMBER(F8),F8/G8,"Undisclosed") -> Undisclosed | J8: =IF(AND(ISNUMBER(F8),ISNUMBER(H8)),F8/H8,"Undisclosed") -> Undisclosed | K8: GRC & penetration testing
B9: 2025 | C9: Solsoft Group | D9: UK | E9: Ekco (Ireland MSP) | F9: Undisclosed | G9: Small | H9: Undisclosed | I9: =IF(ISNUMBER(F9),F9/G9,"Undisclosed") -> Undisclosed | J9: =IF(AND(ISNUMBER(F9),ISNUMBER(H9)),F9/H9,"Undisclosed") -> Undisclosed | K9: MSP for SMEs
B10: 2023 | C10: BJSS | D10: UK | E10: CGI Inc | F10: 700 | G10: 301 | H10: 54 | I10: =IF(ISNUMBER(F10),F10/G10,"Undisclosed") -> 2.3255814 | J10: =IF(AND(ISNUMBER(F10),ISNUMBER(H10)),F10/H10,"Undisclosed") -> 12.962963 | K10: Digital transformation consulting
B11: 2022 | C11: Planalyse BV | D11: Netherlands | E11: Kainos Group | F11: Undisclosed | G11: Small | H11: Undisclosed | I11: =IF(ISNUMBER(F11),F11/G11,"Undisclosed") -> Undisclosed | J11: =IF(AND(ISNUMBER(F11),ISNUMBER(H11)),F11/H11,"Undisclosed") -> Undisclosed | K11: Workday Adaptive Planning
B12: 2022 | C12: Blackline Group Inc | D12: USA | E12: Kainos Group | F12: Undisclosed | G12: Small | H12: Undisclosed | I12: =IF(ISNUMBER(F12),F12/G12,"Undisclosed") -> Undisclosed | J12: =IF(AND(ISNUMBER(F12),ISNUMBER(H12)),F12/H12,"Undisclosed") -> Undisclosed | K12: Workday Strategic Sourcing
B13: 2025 | C13: CyberCrowd | D13: UK | E13: Limerston Capital (PE) | F13: Undisclosed | G13: Small | H13: Undisclosed | I13: =IF(ISNUMBER(F13),F13/G13,"Undisclosed") -> Undisclosed | J13: =IF(AND(ISNUMBER(F13),ISNUMBER(H13)),F13/H13,"Undisclosed") -> Undisclosed | K13: Cybersecurity consultancy
B14: 2025 | C14: DigitalXRAID | D14: UK | E14: Limerston Capital (PE) | F14: Undisclosed | G14: Small | H14: Undisclosed | I14: =IF(ISNUMBER(F14),F14/G14,"Undisclosed") -> Undisclosed | J14: =IF(AND(ISNUMBER(F14),ISNUMBER(H14)),F14/H14,"Undisclosed") -> Undisclosed | K14: Managed security (MSSP)
B15: 2025 | C15: 40fi | D15: UK | E15: Vorboss | F15: Undisclosed | G15: Small-mid | H15: Undisclosed | I15: =IF(ISNUMBER(F15),F15/G15,"Undisclosed") -> Undisclosed | J15: =IF(AND(ISNUMBER(F15),ISNUMBER(H15)),F15/H15,"Undisclosed") -> Undisclosed | K15: Managed cybersecurity
B16: 2025 | C16: Armadillo Managed Services | D16: UK | E16: Transputec | F16: Undisclosed | G16: Small-mid | H16: Undisclosed | I16: =IF(ISNUMBER(F16),F16/G16,"Undisclosed") -> Undisclosed | J16: =IF(AND(ISNUMBER(F16),ISNUMBER(H16)),F16/H16,"Undisclosed") -> Undisclosed | K16: Cyber resilience & infrastructure
B17: 2024 | C17: Technique Ltd | D17: UK | E17: Pixel Holdco (Chiltern PE) | F17: Undisclosed | G17: Small-mid | H17: Undisclosed | I17: =IF(ISNUMBER(F17),F17/G17,"Undisclosed") -> Undisclosed | J17: =IF(AND(ISNUMBER(F17),ISNUMBER(H17)),F17/H17,"Undisclosed") -> Undisclosed | K17: IT managed services
B18: 2024 | C18: Elastacloud | D18: UK | E18: Acora | F18: Undisclosed | G18: Small-mid | H18: Undisclosed | I18: =IF(ISNUMBER(F18),F18/G18,"Undisclosed") -> Undisclosed | J18: =IF(AND(ISNUMBER(F18),ISNUMBER(H18)),F18/H18,"Undisclosed") -> Undisclosed | K18: Data & AI for enterprises
B19: 2024 | C19: Engine B | D19: UK | E19: CLA UK | F19: Undisclosed | G19: Small | H19: Undisclosed | I19: =IF(ISNUMBER(F19),F19/G19,"Undisclosed") -> Undisclosed | J19: =IF(AND(ISNUMBER(F19),ISNUMBER(H19)),F19/H19,"Undisclosed") -> Undisclosed | K19: Generative AI solutions
B20: 2024 | C20: 3DOT Solutions | D20: UK | E20: Nortal | F20: Undisclosed | G20: Small | H20: Undisclosed | I20: =IF(ISNUMBER(F20),F20/G20,"Undisclosed") -> Undisclosed | J20: =IF(AND(ISNUMBER(F20),ISNUMBER(H20)),F20/H20,"Undisclosed") -> Undisclosed | K20: UK Armed Forces cyber
B21: 2024 | C21: Cyphra | D21: UK | E21: Pixel Holdco (Chiltern PE) | F21: Undisclosed | G21: Small | H21: Undisclosed | I21: =IF(ISNUMBER(F21),F21/G21,"Undisclosed") -> Undisclosed | J21: =IF(AND(ISNUMBER(F21),ISNUMBER(H21)),F21/H21,"Undisclosed") -> Undisclosed | K21: Cybersecurity specialist
B23: 25th Percentile | I23: 1.54 | J23: 10.83
B24: Median | I24: 2.05 | J24: 14.68
B25: 75th Percentile | I25: 2.46 | J25: 25.67
