Workbook

Sheet P2 Netflix
B2: Date | C2: Open | D2: High | E2: Low | F2: Close | G2: Adj Close \ | H2: Monthly Return
B3: 43435 | C3: 293.19 | D3: 298.72 | E3: 231.23 | F3: 267.66 | G3: 267.66
B4: 43466 | C4: 259.28 | D4: 358.85001 | E4: 256.57999 | F4: 339.5 | G4: 339.5 | H4: =(G4-G3)/G3 -> 0.26840019
B5: 43497 | C5: 337.17999 | D5: 371.48999 | E5: 336.5 | F5: 358.10001 | G5: 358.10001 | H5: =(G5-G4)/G4 -> 0.054786468
B6: 43525 | C6: 362.26001 | D6: 379 | E6: 342.47 | F6: 356.56 | G6: 356.56 | H6: =(G6-G5)/G5 -> -0.004300497
B7: 43556 | C7: 359 | D7: 384.79999 | E7: 342.26999 | F7: 370.54001 | G7: 370.54001 | H7: =(G7-G6)/G6 -> 0.039208019
B8: 43586 | C8: 374 | D8: 385.98999 | E8: 341.39002 | F8: 343.28 | G8: 343.28 | H8: =(G8-G7)/G7 -> -0.073568331
B9: 43617 | C9: 343.56 | D9: 375 | E9: 332.64999 | F9: 367.32001 | G9: 367.32001 | H9: =(G9-G8)/G8 -> 0.070030319
B10: 43647 | C10: 373.5 | D10: 384.76001 | E10: 305.81 | F10: 322.98999 | G10: 322.98999 | H10: =(G10-G9)/G9 -> -0.12068501
B11: 43678 | C11: 324.25 | D11: 328.57999 | E11: 287.20001 | F11: 293.75 | G11: 293.75 | H11: =(G11-G10)/G10 -> -0.09052909
B12: 43709 | C12: 290.82001 | D12: 301.54999 | E12: 252.28 | F12: 267.62 | G12: 267.62 | H12: =(G12-G11)/G11 -> -0.088953209
B13: 43739 | C13: 267.35001 | D13: 308.75 | E13: 257.01001 | F13: 287.41 | G13: 287.41 | H13: =(G13-G12)/G12 -> 0.07394817
B14: 43770 | C14: 288.70001 | D14: 316.82001 | E14: 281.14002 | F14: 314.66 | G14: 314.66 | H14: =(G14-G13)/G13 -> 0.094812288
B15: 43800 | C15: 314.39002 | D15: 338 | E15: 292.01999 | F15: 323.57001 | G15: 323.57001 | H15: =(G15-G14)/G14 -> 0.028316287
... B63: 45261 | C63: 473.17001 | D63: 500.89002 | E63: 445.73001 | F63: 486.88 | G63: 486.88 | H63: =(G63-G62)/G62 -> 0.027238019
F65: 22-23 Return | G65: =G63/G51-1 -> 0.65111231

Sheet P2 PDD
B3: Date | C3: Open | D3: High | E3: Low | F3: Close | G3: Adj Close \ | H3: Monthly Return
B4: 43435 | C4: 24.33 | D4: 25 | E4: 19.92 | F4: 22.440001 | G4: 22.440001
B5: 43466 | C5: 22 | D5: 30.4 | E5: 21.5 | F5: 29.209999 | G5: 29.209999 | H5: =(G5-G4)/G4 -> 0.3016933
B6: 43497 | C6: 28.93 | D6: 31.18 | E6: 25.5 | F6: 29.940001 | G6: 29.940001 | H6: =(G6-G5)/G5 -> 0.024991511
B7: 43525 | C7: 30.27 | D7: 31.99 | E7: 23.01 | F7: 24.799999 | G7: 24.799999 | H7: =(G7-G6)/G6 -> -0.17167675
B8: 43556 | C8: 25.530001 | D8: 25.66 | E8: 21.299999 | F8: 22.23 | G8: 22.23 | H8: =(G8-G7)/G7 -> -0.103629
B9: 43586 | C9: 22.18 | D9: 24.040001 | E9: 19.120001 | F9: 19.42 | G9: 19.42 | H9: =(G9-G8)/G8 -> -0.12640576
B10: 43617 | C10: 19.379999 | D10: 21.780001 | E10: 18.459999 | F10: 20.629999 | G10: 20.629999 | H10: =(G10-G9)/G9 -> 0.062306849
B11: 43647 | C11: 21.299999 | D11: 22.799999 | E11: 19.110001 | F11: 22.27 | G11: 22.27 | H11: =(G11-G10)/G10 -> 0.079495932
B12: 43678 | C12: 22.200001 | D12: 33.880001 | E12: 21.219999 | F12: 32.77 | G12: 32.77 | H12: =(G12-G11)/G11 -> 0.4714863
B13: 43709 | C13: 32.68 | D13: 36.889999 | E13: 30.02 | F13: 32.220001 | G13: 32.220001 | H13: =(G13-G12)/G12 -> -0.016783613
B14: 43739 | C14: 32.349998 | D14: 42.849998 | E14: 30.65 | F14: 40.880001 | G14: 40.880001 | H14: =(G14-G13)/G13 -> 0.26877715
B15: 43770 | C15: 41.5 | D15: 45.25 | E15: 30.26 | F15: 35.950001 | G15: 35.950001 | H15: =(G15-G14)/G14 -> -0.12059687
B16: 43800 | C16: 35.860001 | D16: 39.619999 | E16: 34.509998 | F16: 37.82 | G16: 37.82 | H16: =(G16-G15)/G15 -> 0.052016661
... B64: 45261 | C64: 143.32001 | D64: 150.66 | E64: 136.22 | F64: 146.31 | G64: 146.31 | H64: =(G64-G63)/G63 -> -0.0076641616
F66: 22-23 Return | G66: =G64/G54-1 -> 0.66773046

Sheet P2 AMD
B3: Date | C3: Open | D3: High | E3: Low | F3: Close | G3: Adj Close \ | H3: Monthly Return
B4: 43435 | C4: 22.48 | D4: 23.75 | E4: 16.030001 | F4: 18.459999 | G4: 18.459999
B5: 43466 | C5: 18.01 | D5: 25.139999 | E5: 16.940001 | F5: 24.41 | G5: 24.41 | H5: =(G5-G4)/G4 -> 0.3223186
B6: 43497 | C6: 24.610001 | D6: 25.52 | E6: 22.27 | F6: 23.530001 | G6: 23.530001 | H6: =(G6-G5)/G5 -> -0.036050758
B7: 43525 | C7: 23.969999 | D7: 28.110001 | E7: 21.040001 | F7: 25.52 | G7: 25.52 | H7: =(G7-G6)/G6 -> 0.08457284
B8: 43556 | C8: 26.42 | D8: 29.950001 | E8: 25.83 | F8: 27.629999 | G8: 27.629999 | H8: =(G8-G7)/G7 -> 0.082680212
B9: 43586 | C9: 28.950001 | D9: 29.67 | E9: 26.030001 | F9: 27.41 | G9: 27.41 | H9: =(G9-G8)/G8 -> -0.0079623238
B10: 43617 | C10: 28.75 | D10: 34.299999 | E10: 27.290001 | F10: 30.370001 | G10: 30.370001 | H10: =(G10-G9)/G9 -> 0.10798982
B11: 43647 | C11: 31.790001 | D11: 34.860001 | E11: 30.1 | F11: 30.450001 | G11: 30.450001 | H11: =(G11-G10)/G10 -> 0.0026341784
B12: 43678 | C12: 30.5 | D12: 35.549999 | E12: 27.65 | F12: 31.450001 | G12: 31.450001 | H12: =(G12-G11)/G11 -> 0.032840721
B13: 43709 | C13: 30.83 | D13: 32.049999 | E13: 28.35 | F13: 28.99 | G13: 28.99 | H13: =(G13-G12)/G12 -> -0.078219425
B14: 43739 | C14: 29.049999 | D14: 34.34 | E14: 27.43 | F14: 33.93 | G14: 33.93 | H14: =(G14-G13)/G13 -> 0.17040359
B15: 43770 | C15: 34.369999 | D15: 41.790001 | E15: 34.099998 | F15: 39.150002 | G15: 39.150002 | H15: =(G15-G14)/G14 -> 0.15384621
B16: 43800 | C16: 39.32 | D16: 47.310001 | E16: 37.150002 | F16: 45.860001 | G16: 45.860001 | H16: =(G16-G15)/G15 -> 0.17139205
... B64: 45261 | C64: 119.88 | D64: 151.05 | E64: 116.37 | F64: 147.41 | G64: 147.41 | H64: =(G64-G63)/G63 -> 0.21665565
F66: 22-23 Return | G66: =G64/G52-1 -> 1.2758995

Sheet P2 FSLR
B2: Date | C2: Open | D2: High | E2: Low | F2: Close | G2: Adj Close \ | H2: Monthly Return
B3: 43435 | C3: 45.900002 | D3: 47.790001 | E3: 38.450001 | F3: 42.459999 | G3: 42.459999
B4: 43466 | C4: 41.630001 | D4: 51.43 | E4: 41.41 | F4: 50.59 | G4: 50.59 | H4: =(G4-G3)/G3 -> 0.19147436
B5: 43497 | C5: 50.779999 | D5: 55.380001 | E5: 47.16 | F5: 52.549999 | G5: 52.549999 | H5: =(G5-G4)/G4 -> 0.038742815
B6: 43525 | C6: 53.080002 | D6: 56.040001 | E6: 49.060001 | F6: 52.84 | G6: 52.84 | H6: =(G6-G5)/G5 -> 0.0055185729
B7: 43556 | C7: 53.290001 | D7: 62.66 | E7: 53.18 | F7: 61.529999 | G7: 61.529999 | H7: =(G7-G6)/G6 -> 0.16445872
B8: 43586 | C8: 62.09 | D8: 63.82 | E8: 56.540001 | F8: 58.040001 | G8: 58.040001 | H8: =(G8-G7)/G7 -> -0.056720267
B9: 43617 | C9: 58 | D9: 66.050003 | E9: 57.400002 | F9: 65.68 | G9: 65.68 | H9: =(G9-G8)/G8 -> 0.13163334
B10: 43647 | C10: 66.300003 | D10: 67.989998 | E10: 64.089996 | F10: 64.489998 | G10: 64.489998 | H10: =(G10-G9)/G9 -> -0.018118179
B11: 43678 | C11: 65.519997 | D11: 69.239998 | E11: 58.57 | F11: 62.07 | G11: 62.07 | H11: =(G11-G10)/G10 -> -0.037525168
B12: 43709 | C12: 61.290001 | D12: 68.550003 | E12: 55.950001 | F12: 58.009998 | G12: 58.009998 | H12: =(G12-G11)/G11 -> -0.065410053
B13: 43739 | C13: 58.400002 | D13: 62.889999 | E13: 50.220001 | F13: 51.790001 | G13: 51.790001 | H13: =(G13-G12)/G12 -> -0.10722284
B14: 43770 | C14: 52.259998 | D14: 55.799999 | E14: 51.43 | F14: 55.240002 | G14: 55.240002 | H14: =(G14-G13)/G13 -> 0.066615195
B15: 43800 | C15: 55.52 | D15: 59 | E15: 52.25 | F15: 55.959999 | G15: 55.959999 | H15: =(G15-G14)/G14 -> 0.013033979
... B63: 45261 | C63: 157.53999 | D63: 177.51 | E63: 137.17 | F63: 172.28 | G63: 172.28 | H63: =(G63-G62)/G62 -> 0.091900115
F65: 22-23 Return | G65: =G63/G51-1 -> 0.15014358

Sheet P2 Shell
C2: Date | D2: Open | E2: High | F2: Low | G2: Close
C3: 43435 | D3: 61.93 | E3: 62.119999 | F3: 55.040001 | G3: 58.27 | H3: Monthly Return
C4: 43466 | D4: 58.27 | E4: 62.34 | F4: 57.720001 | G4: 61.73 | H4: =(G4-G3)/G3 -> 0.059378754
C5: 43497 | D5: 62.259998 | E5: 63.976501 | F5: 61.970001 | G5: 62.209999 | H5: =(G5-G4)/G4 -> 0.0077757816
C6: 43525 | D6: 62.23 | E6: 64.735001 | F6: 60.299999 | G6: 62.59 | H6: =(G6-G5)/G5 -> 0.0061083589
C7: 43556 | D7: 63.419998 | E7: 65.410004 | F7: 62.59 | G7: 63.529999 | H7: =(G7-G6)/G6 -> 0.015018358
C8: 43586 | D8: 63.5 | E8: 64.919998 | F8: 61.669998 | G8: 61.810001 | H8: =(G8-G7)/G7 -> -0.027073792
C9: 43617 | D9: 62.369999 | E9: 66.480003 | F9: 61.810001 | G9: 65.07 | H9: =(G9-G8)/G8 -> 0.052742258
C10: 43647 | D10: 66.360001 | E10: 66.360001 | F10: 62.439999 | G10: 62.889999 | H10: =(G10-G9)/G9 -> -0.033502397
C11: 43678 | D11: 59.560001 | E11: 60 | F11: 54.779999 | G11: 55.599998 | H11: =(G11-G10)/G10 -> -0.1159167
C12: 43709 | D12: 55.599998 | E12: 59.32 | F12: 54.560001 | G12: 58.849998 | H12: =(G12-G11)/G11 -> 0.05845324
C13: 43739 | D13: 58.669998 | E13: 60.195 | F13: 56.130001 | G13: 57.970001 | H13: =(G13-G12)/G12 -> -0.014953221
C14: 43770 | D14: 58.220001 | E14: 60.509998 | F14: 57.279999 | G14: 57.490002 | H14: =(G14-G13)/G13 -> -0.0082801275
C15: 43800 | D15: 57.630001 | E15: 59.525002 | F15: 56.029999 | G15: 58.98 | H15: =(G15-G14)/G14 -> 0.025917515
... C63: 45261 | D63: 65.709999 | E63: 66.360001 | F63: 63.029999 | G63: 65.800003 | H63: =(G63-G62)/G62 -> 0
F65: 22-23 Return | G65: =G63/G51-1 -> 0.15539951

Sheet P2 JNJ
C2: Date | D2: Open | E2: High | F2: Low | G2: Close | H2: Adj Close \
C3: 43435 | D3: 145.57001 | E3: 148.99 | F3: 121 | G3: 129.05 | H3: 110.13247 | J3: Return (%)
C4: 43466 | D4: 128.13001 | E4: 135.19 | F4: 125 | G4: 133.08 | H4: 113.57168 | I4: =H4/H3-1 -> 0.03122793 | J4: =I4*100 -> 3.122793
C5: 43497 | D5: 134.02 | E5: 137.95 | F5: 131.26 | G5: 136.64 | H5: 116.60981 | I5: =H5/H4-1 -> 0.026750789 | J5: =I5*100 -> 2.6750789
C6: 43525 | D6: 137.22 | E6: 140 | F6: 135.74 | G6: 139.78999 | H6: 120.0893 | I6: =H6/H5-1 -> 0.029838759 | J6: =I6*100 -> 2.9838759
C7: 43556 | D7: 139.99 | E7: 141.45 | F7: 134.42 | G7: 141.2 | H7: 121.30059 | I7: =H7/H6-1 -> 0.010086569 | J7: =I7*100 -> 1.0086569
C8: 43586 | D8: 140.95 | E8: 142.35001 | F8: 128.52 | G8: 131.14999 | H8: 112.66692 | I8: =H8/H7-1 -> -0.071175869 | J8: =I8*100 -> -7.1175869
C9: 43617 | D9: 131.5 | E9: 144.98 | F9: 131.03999 | G9: 139.28 | H9: 120.46985 | I9: =H9/H8-1 -> 0.069256649 | J9: =I9*100 -> 6.9256649
C10: 43647 | D10: 140.2 | E10: 142.47 | F10: 127.84 | G10: 130.22 | H10: 112.63343 | I10: =H10/H9-1 -> -0.065048799 | J10: =I10*100 -> -6.5048799
C11: 43678 | D11: 130.26 | E11: 134.10001 | F11: 126.63 | G11: 128.36 | H11: 111.02463 | I11: =H11/H10-1 -> -0.014283521 | J11: =I11*100 -> -1.4283521
C12: 43709 | D12: 127.99 | E12: 132.78 | F12: 126.34 | G12: 129.38001 | H12: 112.74543 | I12: =H12/H11-1 -> 0.015499282 | J12: =I12*100 -> 1.5499282
C13: 43739 | D13: 130.02 | E13: 137.49 | F13: 126.1 | G13: 132.03999 | H13: 115.0634 | I13: =H13/H12-1 -> 0.020559326 | J13: =I13*100 -> 2.0559326
C14: 43770 | D14: 132.05 | E14: 138.63001 | F14: 129.67999 | G14: 137.49 | H14: 119.81274 | I14: =H14/H13-1 -> 0.041275827 | J14: =I14*100 -> 4.1275827
C15: 43800 | D15: 137.72 | E15: 147.84 | F15: 136.16 | G15: 145.86999 | H15: 127.99601 | I15: =H15/H14-1 -> 0.068300526 | J15: =I15*100 -> 6.8300526
... C63: 45261 | D63: 156.44 | E63: 160.02 | F63: 151.77 | G63: 156.74 | H63: 153.14911 | I63: =H63/H62-1 -> 0.021564679 | J63: =I63*100 -> 2.1564679
G65: 22-23 Return | H65: =H63/H51-1 -> -0.085783813

Sheet CAPM Regression
I2: Problem 3
B3: Date | C3: Netflix (%) | D3: PDD(%) | E3: AMD (%) | F3: FSLR (%) | G3: Shell (%) | H3: JNJ (%) | I3: Excess Netflix (%) | J3: Excess PDD (%) | K3: Excess AMD (%) | L3: Excess FSLR (%) | M3: Excess Shell (%) | N3: Excess JNJ (%) | O3: Excess Market Return (%) | P3: Risk Free (%)
B4: 43466 | C4: 26.840019 | D4: 30.16933 | E4: 32.23186 | F4: 19.147436 | G4: 5.9378754 | H4: 3.122793 | I4: =C4-P4 -> 26.630019 | J4: =D4-P4 -> 29.95933 | K4: =E4-P4 -> 32.02186 | L4: =F4-P4 -> 18.937436 | M4: =G4-P4 -> 5.7278754 | N4: =H4-P4 -> 2.912793 | O4: 8.4 | P4: 0.21
B5: 43497 | C5: 5.4786468 | D5: 2.4991511 | E5: -3.6050758 | F5: 3.8742815 | G5: 0.77757816 | H5: 2.6750789 | I5: =C5-P5 -> 5.2986468 | J5: =D5-P5 -> 2.3191511 | K5: =E5-P5 -> -3.7850758 | L5: =F5-P5 -> 3.6942815 | M5: =G5-P5 -> 0.59757816 | N5: =H5-P5 -> 2.4950789 | O5: 3.4 | P5: 0.18
B6: 43525 | C6: -0.4300497 | D6: -17.167675 | E6: 8.457284 | F6: 0.55185729 | G6: 0.61083589 | H6: 2.9838759 | I6: =C6-P6 -> -0.6200497 | J6: =D6-P6 -> -17.357675 | K6: =E6-P6 -> 8.267284 | L6: =F6-P6 -> 0.36185729 | M6: =G6-P6 -> 0.42083589 | N6: =H6-P6 -> 2.7938759 | O6: 1.1 | P6: 0.19
B7: 43556 | C7: 3.9208019 | D7: -10.3629 | E7: 8.2680212 | F7: 16.445872 | G7: 1.5018358 | H7: 1.0086569 | I7: =C7-P7 -> 3.7108019 | J7: =D7-P7 -> -10.5729 | K7: =E7-P7 -> 8.0580212 | L7: =F7-P7 -> 16.235872 | M7: =G7-P7 -> 1.2918358 | N7: =H7-P7 -> 0.79865687 | O7: 3.97 | P7: 0.21
B8: 43586 | C8: -7.3568331 | D8: -12.640576 | E8: -0.79623238 | F8: -5.6720267 | G8: -2.7073792 | H8: -7.1175869 | I8: =C8-P8 -> -7.5668331 | J8: =D8-P8 -> -12.850576 | K8: =E8-P8 -> -1.0062324 | L8: =F8-P8 -> -5.8820267 | M8: =G8-P8 -> -2.9173792 | N8: =H8-P8 -> -7.3275869 | O8: -6.94 | P8: 0.21
B9: 43617 | C9: 7.0030319 | D9: 6.2306849 | E9: 10.798982 | F9: 13.163334 | G9: 5.2742258 | H9: 6.9256649 | I9: =C9-P9 -> 6.8230319 | J9: =D9-P9 -> 6.0506849 | K9: =E9-P9 -> 10.618982 | L9: =F9-P9 -> 12.983334 | M9: =G9-P9 -> 5.0942258 | N9: =H9-P9 -> 6.7456649 | O9: 6.93 | P9: 0.18
B10: 43647 | C10: -12.068501 | D10: 7.9495932 | E10: 0.26341784 | F10: -1.8118179 | G10: -3.3502397 | H10: -6.5048799 | I10: =C10-P10 -> -12.258501 | J10: =D10-P10 -> 7.7595932 | K10: =E10-P10 -> 0.073417838 | L10: =F10-P10 -> -2.0018179 | M10: =G10-P10 -> -3.5402397 | N10: =H10-P10 -> -6.6948799 | O10: 1.19 | P10: 0.19
B11: 43678 | C11: -9.052909 | D11: 47.14863 | E11: 3.2840721 | F11: -3.7525168 | G11: -11.59167 | H11: -1.4283521 | I11: =C11-P11 -> -9.212909 | J11: =D11-P11 -> 46.98863 | K11: =E11-P11 -> 3.1240721 | L11: =F11-P11 -> -3.9125168 | M11: =G11-P11 -> -11.75167 | N11: =H11-P11 -> -1.5883521 | O11: -2.58 | P11: 0.16
B12: 43709 | C12: -8.8953209 | D12: -1.6783613 | E12: -7.8219425 | F12: -6.5410053 | G12: 5.845324 | H12: 1.5499282 | I12: =C12-P12 -> -9.0753209 | J12: =D12-P12 -> -1.8583613 | K12: =E12-P12 -> -8.0019425 | L12: =F12-P12 -> -6.7210053 | M12: =G12-P12 -> 5.665324 | N12: =H12-P12 -> 1.3699282 | O12: 1.43 | P12: 0.18
B13: 43739 | C13: 7.394817 | D13: 26.877715 | E13: 17.040359 | F13: -10.722284 | G13: -1.4953221 | H13: 2.0559326 | I13: =C13-P13 -> 7.234817 | J13: =D13-P13 -> 26.717715 | K13: =E13-P13 -> 16.880359 | L13: =F13-P13 -> -10.882284 | M13: =G13-P13 -> -1.6553221 | N13: =H13-P13 -> 1.8959326 | O13: 2.06 | P13: 0.16
B14: 43770 | C14: 9.4812288 | D14: -12.059687 | E14: 15.384621 | F14: 6.6615195 | G14: -0.82801275 | H14: 4.1275827 | I14: =C14-P14 -> 9.3612288 | J14: =D14-P14 -> -12.179687 | K14: =E14-P14 -> 15.264621 | L14: =F14-P14 -> 6.5415195 | M14: =G14-P14 -> -0.94801275 | N14: =H14-P14 -> 4.0075827 | O14: 3.88 | P14: 0.12
B15: 43800 | C15: 2.8316287 | D15: 5.2016661 | E15: 17.139205 | F15: 1.3033979 | G15: 2.5917515 | H15: 6.8300526 | I15: =C15-P15 -> 2.6916287 | J15: =D15-P15 -> 5.0616661 | K15: =E15-P15 -> 16.999205 | L15: =F15-P15 -> 1.1633979 | M15: =G15-P15 -> 2.4517515 | N15: =H15-P15 -> 6.6900526 | O15: 2.77 | P15: 0.14
... B63: 45261 | C63: 2.7238019 | D63: -0.76641616 | E63: 21.665565 | F63: 9.1900115 | G63: 0 | H63: 2.1564679 | I63: =C63-P63 -> 2.2938019 | J63: =D63-P63 -> -1.1964162 | K63: =E63-P63 -> 21.235565 | L63: =F63-P63 -> 8.7600115 | M63: =G63-P63 -> -0.43 | N63: =H63-P63 -> 1.7264679 | O63: 4.87 | P63: 0.43
I64: =AVERAGE(I4:I63) -> 1.6789805
M67: E (Rm) | O67: =AVERAGE(O4:O63) -> 1.185
M68: Variance (Rm) | O68: =_xlfn.VAR.S(O4:O63) -> 30.910951
C70: Problem 4 Regression Results
B72: Netflix | M72: PDD
B73: SUMMARY OUTPUT | M73: SUMMARY OUTPUT
B75: Regression Statistics | M75: Regression Statistics
B76: Multiple R | C76: 0.58545717 | M76: Multiple R | N76: 0.23709709
B77: R Square | C77: 0.3427601 | M77: R Square | N77: 0.056215032
B78: Adjusted R Square | C78: 0.33142837 | M78: Adjusted R Square | N78: 0.039942877
B79: Standard Error | C79: 9.9063426 | M79: Standard Error | N79: 19.876915
B80: Observations | C80: 60 | M80: Observations | N80: 60
B82: ANOVA | M82: ANOVA
C83: df | D83: SS | E83: MS | F83: F | G83: Significance F | N83: df | O83: SS | P83: MS | Q83: F | R83: Significance F
B84: Regression | C84: 1 | D84: 2968.3903 | E84: 2968.3903 | F84: 30.247837 | G84: 8.951771e-07 | M84: Regression | N84: 1 | O84: 1364.9142 | P84: 1364.9142 | Q84: 3.4546766 | R84: 0.068149482
B85: Residual | C85: 58 | D85: 5691.8661 | E85: 98.135623 | M85: Residual | N85: 58 | O85: 22915.321 | P85: 395.09174
B86: Total | C86: 59 | D86: 8660.2565 | M86: Total | N86: 59 | O86: 24280.235
C88: Coefficients | D88: Standard Error | E88: t Stat | F88: P-value | G88: Lower 95% | H88: Upper 95% | I88: Lower 95.0% | J88: Upper 95.0% | N88: Coefficients | O88: Standard Error | P88: t Stat | Q88: P-value | R88: Lower 95% | S88: Upper 95% | T88: Lower 95.0% | U88: Upper 95.0%
B89: Intercept | C89: 0.16717244 | D89: 1.3081112 | E89: 0.12779681 | F89: 0.89875185 | G89: -2.4512966 | H89: 2.7856415 | I89: -2.4512966 | J89: 2.7856415 | M89: Intercept | N89: 3.8172041 | O89: 2.6247038 | P89: 1.4543371 | Q89: 0.15124336 | R89: -1.4367114 | S89: 9.0711196 | T89: -1.4367114 | U89: 9.0711196
B90: Beta | C90: 1.2757874 | D90: 0.23196964 | E90: 5.4998034 | F90: 8.951771e-07 | G90: 0.81144973 | H90: 1.7401251 | I90: 0.81144973 | J90: 1.7401251 | M90: Beta | N90: 0.86510832 | O90: 0.4654433 | P90: 1.858676 | Q90: 0.068149482 | R90: -0.066577684 | S90: 1.7967943 | T90: -0.066577684 | U90: 1.7967943
B94: AMD | M94: FSLR
B95: SUMMARY OUTPUT | M95: SUMMARY OUTPUT
B97: Regression Statistics | M97: Regression Statistics
B98: Multiple R | C98: 0.58810552 | M98: Multiple R | N98: 0.55690328
B99: R Square | C99: 0.3458681 | M99: R Square | N99: 0.31014126
...

Sheet Active Porfolio
C3: Market Portfolio
C4: Excess Market Return (%) | D4: ='CAPM Regression'!O67 -> 1.185
C5: Variance (%) | D5: ='CAPM Regression'!O68 -> 30.910951
C6: Ratio | D6: =D4/D5 -> 0.038335928
C10: Seleted Stocks | D10: Expected Monthly Excess Return | E10: FC Monthly Excess Return | F10: Alpha (Forecast) | G10: Beta | H10: Std.Error | I10: Residual Variance
C11: Netflix | D11: =G11*$D$4 -> 1.5118081 | E11: 2.08 | F11: =E11-D11 -> 0.56819191 | G11: ='CAPM Regression'!C90 -> 1.2757874 | H11: ='CAPM Regression'!C79 -> 9.9063426 | I11: =H11^2 -> 98.135623
C12: PDD | D12: =G12*$D$4 -> 1.0251534 | E12: 1.705 | F12: =E12-D12 -> 0.67984665 | G12: ='CAPM Regression'!N90 -> 0.86510832 | H12: ='CAPM Regression'!N79 -> 19.876915 | I12: =H12^2 -> 395.09174
C13: AMD | D13: =G13*$D$4 -> 1.9338156 | E13: 2.55 | F13: =E13-D13 -> 0.61618443 | G13: ='CAPM Regression'!C112 -> 1.6319119 | H13: ='CAPM Regression'!C101 -> 12.584684 | I13: =H13^2 -> 158.37426
C14: FSLR | D14: =G14*$D$4 -> 1.7265813 | E14: 2.35 | F14: =E14-D14 -> 0.62341874 | G14: ='CAPM Regression'!N112 -> 1.4570306 | H14: ='CAPM Regression'!N101 -> 12.185327 | I14: =H14^2 -> 148.48218
C15: Shell | D15: =G15*$D$4 -> 0.73262299 | E15: 1.18 | F15: =E15-D15 -> 0.44737701 | G15: ='CAPM Regression'!C135 -> 0.61824725 | H15: ='CAPM Regression'!C124 -> 7.606765 | I15: =H15^2 -> 57.862874
C16: JNJ | D16: =G16*$D$4 -> 0.56937996 | E16: 0.755 | F16: =E16-D16 -> 0.18562004 | G16: ='CAPM Regression'!N135 -> 0.48048942 | H16: ='CAPM Regression'!N124 -> 4.3658231 | I16: =H16^2 -> 19.060412
C18: Seleted Stocks | D18: Initial Weight (Alpha/Variance) | E18: Weight (IW/SUM) | F18: Individual Risk Premium
C19: Netflix | D19: =F11/I11 -> 0.005789864 | E19: =D19/$D$25 -> 0.17507863 | F19: =D11*E19 -> 0.26468529
C20: PDD | D20: =F12/I12 -> 0.0017207311 | E20: =D20/$D$25 -> 0.052032871 | F20: =D12*E20 -> 0.053341672
C21: AMD | D21: =F13/I13 -> 0.0038906854 | E21: =D21/$D$25 -> 0.11764972 | F21: =D13*E21 -> 0.22751286
C22: FSLR | D22: =F14/I14 -> 0.0041986098 | E22: =D22/$D$25 -> 0.12696099 | F22: =D14*E22 -> 0.21920846
C23: Shell | D23: =F15/I15 -> 0.0077316763 | E23: =D23/$D$25 -> 0.23379674 | F23: =D15*E23 -> 0.17128486
C24: JNJ | D24: =F16/I16 -> 0.0097385115 | E24: =D24/$D$25 -> 0.29448105 | F24: =D16*E24 -> 0.16767161
C25: Sum | D25: =SUM(D19:D24) -> 0.033070078 | E25: =SUM(E19:E24) -> 1 | F25: =SUM(F19:F24) -> 1.1037048
C27: Active Portfolio
C28: Alpha (M) | D28: =F11*E19+F12*E20+F13*E21+F14*E22+F15*E23+F16*E24 -> 0.44575329
C29: Residual Variance | D29: =I11*E19^2+I12*E20^2+I13*E21^2+I14*E22^2+I15*E23^2+I16*E24^2 -> 13.479052
C30: Ratio | D30: =D28/D29 -> 0.033070078
C31: Initial Position=A/M (ratios) | D31: =D30/D6 -> 0.86263929
C32: Beta of the active portfolio | D32: =G11*E19+G12*E20+G13*E21+G14*E22+G15*E23+G16*E24 -> 0.93139642
C33: Adjusted Position for Active Portfolio | D33: =D31/(1+D31-D31*D32) -> 0.81444058
C34: Final Weight for Market Portfolio | D34: =1-D33 -> 0.18555942
C36: Adjusted Weight for Each Stock
D37: Weight
C38: Netflix | D38: =$D$33*E19 -> 0.14259114
C39: PDD | D39: =$D$33*E20 -> 0.042377682
C40: AMD | D40: =$D$33*E21 -> 0.095818707
C41: FSLR | D41: =$D$33*E22 -> 0.10340218
C42: Shell | D42: =$D$33*E23 -> 0.19041355
C43: JNJ | D43: =$D$33*E24 -> 0.23983732
C44: Sum | D44: =SUM(D38:D43) -> 0.81444058
D46: Active Portfolio
C47: Beta | D47: =D34+D33*D32 -> 0.94412646
C48: Risk Premium | D48: =D47*D4+D33*D28 -> 1.4818294
C49: Variance | D49: =D47^2+D33^2*D29 -> 9.8322111
...

Sheet selection
N1: Weights
C2: Excess Market | D2: SMB | E2: HML | F2: RF | G2: A | H2: B | I2: C | J2: D | K2: E | L2: f | N2: passive P | O2: Wa | P2: Wb | Q2: Wc | R2: Wd | S2: We | T2: Wf | V2: Excess
B3: 201901 | C3: 8.4 | D3: 2.88 | E3: -0.45 | F3: 0.21 | G3: 26.630019 | H3: 29.95933 | I3: 32.02186 | J3: 18.937436 | K3: 5.7278754 | L3: 2.912793 | N3: ='Active Porfolio'!D34 -> 0.18555942 | O3: ='Active Porfolio'!D38 -> 0.14259114 | P3: ='Active Porfolio'!D39 -> 0.042377682 | Q3: ='Active Porfolio'!D40 -> 0.095818707 | R3: ='Active Porfolio'!D41 -> 0.10340218 | S3: ='Active Porfolio'!D42 -> 0.19041355 | T3: ='Active Porfolio'!D43 -> 0.23983732 | V3: =C3*$N$3+G3*$O$3+H3*$P$3+I3*$Q$3+J3*$R$3+K3*$S$3+L3*$T$3 -> 13.441238
B4: 201902 | C4: 3.4 | D4: 2.06 | E4: -2.71 | F4: 0.18 | G4: 5.2986468 | H4: 2.3191511 | I4: -3.7850758 | J4: 3.6942815 | K4: 0.59757816 | L4: 2.4950789 | V4: =C4*$N$3+G4*$O$3+H4*$P$3+I4*$Q$3+J4*$R$3+K4*$S$3+L4*$T$3 -> 2.2162381
B5: 201903 | C5: 1.1 | D5: -3.05 | E5: -4.12 | F5: 0.19 | G5: -0.6200497 | H5: -17.357675 | I5: 8.267284 | J5: 0.36185729 | K5: 0.42083589 | L5: 2.7938759 | V5: =C5*$N$3+G5*$O$3+H5*$P$3+I5*$Q$3+J5*$R$3+K5*$S$3+L5*$T$3 -> 0.9599096
B6: 201904 | C6: 3.97 | D6: -1.72 | E6: 2.16 | F6: 0.21 | G6: 3.7108019 | H6: -10.5729 | I6: 8.0580212 | J6: 16.235872 | K6: 1.2918358 | L6: 0.79865687 | V6: =C6*$N$3+G6*$O$3+H6*$P$3+I6*$Q$3+J6*$R$3+K6*$S$3+L6*$T$3 -> 3.7062079
B7: 201905 | C7: -6.94 | D7: -1.31 | E7: -2.37 | F7: 0.21 | G7: -7.5668331 | H7: -12.850576 | I7: -1.0062324 | J7: -5.8820267 | K7: -2.9173792 | L7: -7.3275869 | V7: =C7*$N$3+G7*$O$3+H7*$P$3+I7*$Q$3+J7*$R$3+K7*$S$3+L7*$T$3 -> -5.928891
B8: 201906 | C8: 6.93 | D8: 0.28 | E8: -0.7 | F8: 0.18 | G8: 6.8230319 | H8: 6.0506849 | I8: 10.618982 | J8: 12.983334 | K8: 5.0942258 | L8: 6.7456649 | V8: =C8*$N$3+G8*$O$3+H8*$P$3+I8*$Q$3+J8*$R$3+K8*$S$3+L8*$T$3 -> 7.4631186
B9: 201907 | C9: 1.19 | D9: -1.93 | E9: 0.47 | F9: 0.19 | G9: -12.258501 | H9: 7.7595932 | I9: 0.073417838 | J9: -2.0018179 | K9: -3.5402397 | L9: -6.6948799 | V9: =C9*$N$3+G9*$O$3+H9*$P$3+I9*$Q$3+J9*$R$3+K9*$S$3+L9*$T$3 -> -3.6780535
B10: 201908 | C10: -2.58 | D10: -2.39 | E10: -4.79 | F10: 0.16 | G10: -9.212909 | H10: 46.98863 | I10: 3.1240721 | J10: -3.9125168 | K10: -11.75167 | L10: -1.5883521 | V10: =C10*$N$3+G10*$O$3+H10*$P$3+I10*$Q$3+J10*$R$3+K10*$S$3+L10*$T$3 -> -2.5249948
B11: 201909 | C11: 1.43 | D11: -0.97 | E11: 6.77 | F11: 0.18 | G11: -9.0753209 | H11: -1.8583613 | I11: -8.0019425 | J11: -6.7210053 | K11: 5.665324 | L11: 1.3699282 | V11: =C11*$N$3+G11*$O$3+H11*$P$3+I11*$Q$3+J11*$R$3+K11*$S$3+L11*$T$3 -> -1.1618515
B12: 201910 | C12: 2.06 | D12: 0.29 | E12: -1.9 | F12: 0.16 | G12: 7.234817 | H12: 26.717715 | I12: 16.880359 | J12: -10.882284 | K12: -1.6553221 | L12: 1.8959326 | V12: =C12*$N$3+G12*$O$3+H12*$P$3+I12*$Q$3+J12*$R$3+K12*$S$3+L12*$T$3 -> 3.1778299
B13: 201911 | C13: 3.88 | D13: 0.78 | E13: -1.99 | F13: 0.12 | G13: 9.3612288 | H13: -12.179687 | I13: 15.264621 | J13: 6.5415195 | K13: -0.94801275 | L13: 4.0075827 | V13: =C13*$N$3+G13*$O$3+H13*$P$3+I13*$Q$3+J13*$R$3+K13*$S$3+L13*$T$3 -> 4.458349
B14: 201912 | C14: 2.77 | D14: 0.73 | E14: 1.78 | F14: 0.14 | G14: 2.6916287 | H14: 5.0616661 | I14: 16.999205 | J14: 1.1633979 | K14: 2.4517515 | L14: 6.6900526 | V14: =C14*$N$3+G14*$O$3+H14*$P$3+I14*$Q$3+J14*$R$3+K14*$S$3+L14*$T$3 -> 4.9328144
B15: 202001 | C15: -0.11 | D15: -3.13 | E15: -6.25 | F15: 0.13 | G15: 6.5207984 | H15: -7.0046668 | I15: 2.3558242 | J15: -11.530996 | K15: -11.710193 | L15: 1.9265852 | V15: =C15*$N$3+G15*$O$3+H15*$P$3+I15*$Q$3+J15*$R$3+K15*$S$3+L15*$T$3 -> -2.1217555
... B62: 202312 | C62: 4.87 | D62: 6.36 | E62: 4.92 | F62: 0.43 | G62: 2.2938019 | H62: -1.1964162 | I62: 21.235565 | J62: 8.7600115 | K62: -0.43 | L62: 1.7264679 | V62: =C62*$N$3+G62*$O$3+H62*$P$3+I62*$Q$3+J62*$R$3+K62*$S$3+L62*$T$3 -> 4.4528112
B66: Netflix | F66: Beta | G66: >1 | L66: PDD | P66: Beta | Q66: <1
F67: SMB | G67: neutral | P67: SMB | Q67: neutral
B68: SUMMARY OUTPUT | F68: HML | G68: growth | L68: SUMMARY OUTPUT | P68: HML | Q68: neutral
B70: Regression Statistics | L70: Regression Statistics
B71: Multiple R | C71: 0.6934629 | L71: Multiple R | M71: 0.34499454
B72: R Square | C72: 0.4808908 | L72: R Square | M72: 0.11902123
B73: Adjusted R Square | C73: 0.45308137 | L73: Adjusted R Square | M73: 0.07182594
B74: Standard Error | C74: 8.9598498 | L74: Standard Error | M74: 19.544076
B75: Observations | C75: 60 | L75: Observations | M75: 60
B77: ANOVA | L77: ANOVA
C78: df | D78: SS | E78: MS | F78: F | G78: Significance F | M78: df | N78: SS | O78: MS | P78: F | Q78: Significance F
B79: Regression | C79: 3 | D79: 4164.6376 | E79: 1388.2125 | F79: 17.29237 | G79: 4.5490694e-08 | L79: Regression | M79: 3 | N79: 2889.8635 | O79: 963.28783 | P79: 2.5218878 | Q79: 0.067009551
B80: Residual | C80: 56 | D80: 4495.6188 | E80: 80.278908 | L80: Residual | M80: 56 | N80: 21390.372 | O80: 381.97092
B81: Total | C81: 59 | D81: 8660.2565 | L81: Total | M81: 59 | N81: 24280.235
C83: Coefficients | D83: Standard Error | E83: t Stat | F83: P-value | G83: Lower 95% | H83: Upper 95% | I83: Lower 95.0% | J83: Upper 95.0% | M83: Coefficients | N83: Standard Error | O83: t Stat | P83: P-value | Q83: Lower 95% | R83: Upper 95% | S83: Lower 95.0% | T83: Upper 95.0%
B84: Intercept | C84: 0.23475666 | D84: 1.1883015 | E84: 0.19755647 | F84: 0.84410744 | G84: -2.1456973 | H84: 2.6152107 | I84: -2.1456973 | J84: 2.6152107 | L84: Intercept | M84: 4.2780718 | N84: 2.5920363 | O84: 1.6504676 | P84: 0.10444557 | Q84: -0.91440084 | R84: 9.4705445 | S84: -0.91440084 | T84: 9.4705445
B85: Excess Market | C85: 1.2251804 | D85: 0.22264245 | E85: 5.5029058 | F85: 9.6352143e-07 | G85: 0.779174 | H85: 1.6711868 | I85: 0.779174 | J85: 1.6711868 | L85: Excess Market | M85: 0.55338108 | N85: 0.48564888 | O85: 1.1394674 | P85: 0.25935886 | Q85: -0.41949052 | R85: 1.5262527 | S85: -0.41949052 | T85: 1.5262527
B86: SMB | C86: 0.5576252 | D86: 0.42444305 | E86: 1.313781 | F86: 0.19427678 | G86: -0.29263639 | H86: 1.4078868 | I86: -0.29263639 | J86: 1.4078868 | L86: SMB | M86: 1.8379978 | N86: 0.92583554 | O86: 1.9852314 | P86: 0.052024477 | Q86: -0.016673652 | R86: 3.6926692 | S86: -0.016673652 | T86: 3.6926692
B87: HML | C87: -0.9123714 | D87: 0.24815507 | E87: -3.676618 | F87: 0.0005311389 | G87: -1.4094858 | H87: -0.41525706 | I87: -1.4094858 | J87: -0.41525706 | L87: HML | M87: -0.16279826 | N87: 0.54129945 | O87: -0.30075454 | P87: 0.76471548 | Q87: -1.2471514 | R87: 0.92155483 | S87: -1.2471514 | T87: 0.92155483
B91: AMD | F91: Beta | G91: >1 | L91: FSLR | P91: Beta | Q91: >1
F92: SMB | G92: neutral | P92: SMB | Q92: neutral
B93: SUMMARY OUTPUT | F93: HML | G93: growth | L93: SUMMARY OUTPUT | P93: HML | Q93: neutral
B95: Regression Statistics | L95: Regression Statistics
B96: Multiple R | C96: 0.66524225 | L96: Multiple R | M96: 0.59773396
...

Sheet SMB+HML
N1: Weights
C2: Excess RP for market portfolio | D2: SMB | E2: HML | F2: RF | G2: A | H2: B | I2: C | J2: D | K2: E | L2: F | N2: Market Portfolio | O2: Wa | P2: Wb | Q2: Wc | R2: Wd | S2: We | T2: Wf | V2: Excess RP for Active Portfolio
B3: 201901 | C3: 8.4 | D3: 2.88 | E3: -0.45 | F3: 0.21 | G3: 26.630019 | H3: 29.95933 | I3: 32.02186 | J3: 18.937436 | K3: 5.7278754 | L3: 2.912793 | N3: ='Active Porfolio'!D34 -> 0.18555942 | O3: ='Active Porfolio'!D38 -> 0.14259114 | P3: ='Active Porfolio'!D39 -> 0.042377682 | Q3: ='Active Porfolio'!D40 -> 0.095818707 | R3: ='Active Porfolio'!D41 -> 0.10340218 | S3: ='Active Porfolio'!D42 -> 0.19041355 | T3: ='Active Porfolio'!D43 -> 0.23983732 | V3: =C3*$N$3+G3*$O$3+H3*$P$3+I3*$Q$3+J3*$R$3+K3*$S$3+L3*$T$3 -> 13.441238
B4: 201902 | C4: 3.4 | D4: 2.06 | E4: -2.71 | F4: 0.18 | G4: 5.2986468 | H4: 2.3191511 | I4: -3.7850758 | J4: 3.6942815 | K4: 0.59757816 | L4: 2.4950789 | V4: =C4*$N$3+G4*$O$3+H4*$P$3+I4*$Q$3+J4*$R$3+K4*$S$3+L4*$T$3 -> 2.2162381
B5: 201903 | C5: 1.1 | D5: -3.05 | E5: -4.12 | F5: 0.19 | G5: -0.6200497 | H5: -17.357675 | I5: 8.267284 | J5: 0.36185729 | K5: 0.42083589 | L5: 2.7938759 | V5: =C5*$N$3+G5*$O$3+H5*$P$3+I5*$Q$3+J5*$R$3+K5*$S$3+L5*$T$3 -> 0.9599096
B6: 201904 | C6: 3.97 | D6: -1.72 | E6: 2.16 | F6: 0.21 | G6: 3.7108019 | H6: -10.5729 | I6: 8.0580212 | J6: 16.235872 | K6: 1.2918358 | L6: 0.79865687 | V6: =C6*$N$3+G6*$O$3+H6*$P$3+I6*$Q$3+J6*$R$3+K6*$S$3+L6*$T$3 -> 3.7062079
B7: 201905 | C7: -6.94 | D7: -1.31 | E7: -2.37 | F7: 0.21 | G7: -7.5668331 | H7: -12.850576 | I7: -1.0062324 | J7: -5.8820267 | K7: -2.9173792 | L7: -7.3275869 | V7: =C7*$N$3+G7*$O$3+H7*$P$3+I7*$Q$3+J7*$R$3+K7*$S$3+L7*$T$3 -> -5.928891
B8: 201906 | C8: 6.93 | D8: 0.28 | E8: -0.7 | F8: 0.18 | G8: 6.8230319 | H8: 6.0506849 | I8: 10.618982 | J8: 12.983334 | K8: 5.0942258 | L8: 6.7456649 | V8: =C8*$N$3+G8*$O$3+H8*$P$3+I8*$Q$3+J8*$R$3+K8*$S$3+L8*$T$3 -> 7.4631186
B9: 201907 | C9: 1.19 | D9: -1.93 | E9: 0.47 | F9: 0.19 | G9: -12.258501 | H9: 7.7595932 | I9: 0.073417838 | J9: -2.0018179 | K9: -3.5402397 | L9: -6.6948799 | V9: =C9*$N$3+G9*$O$3+H9*$P$3+I9*$Q$3+J9*$R$3+K9*$S$3+L9*$T$3 -> -3.6780535
B10: 201908 | C10: -2.58 | D10: -2.39 | E10: -4.79 | F10: 0.16 | G10: -9.212909 | H10: 46.98863 | I10: 3.1240721 | J10: -3.9125168 | K10: -11.75167 | L10: -1.5883521 | V10: =C10*$N$3+G10*$O$3+H10*$P$3+I10*$Q$3+J10*$R$3+K10*$S$3+L10*$T$3 -> -2.5249948
B11: 201909 | C11: 1.43 | D11: -0.97 | E11: 6.77 | F11: 0.18 | G11: -9.0753209 | H11: -1.8583613 | I11: -8.0019425 | J11: -6.7210053 | K11: 5.665324 | L11: 1.3699282 | V11: =C11*$N$3+G11*$O$3+H11*$P$3+I11*$Q$3+J11*$R$3+K11*$S$3+L11*$T$3 -> -1.1618515
B12: 201910 | C12: 2.06 | D12: 0.29 | E12: -1.9 | F12: 0.16 | G12: 7.234817 | H12: 26.717715 | I12: 16.880359 | J12: -10.882284 | K12: -1.6553221 | L12: 1.8959326 | V12: =C12*$N$3+G12*$O$3+H12*$P$3+I12*$Q$3+J12*$R$3+K12*$S$3+L12*$T$3 -> 3.1778299
B13: 201911 | C13: 3.88 | D13: 0.78 | E13: -1.99 | F13: 0.12 | G13: 9.3612288 | H13: -12.179687 | I13: 15.264621 | J13: 6.5415195 | K13: -0.94801275 | L13: 4.0075827 | V13: =C13*$N$3+G13*$O$3+H13*$P$3+I13*$Q$3+J13*$R$3+K13*$S$3+L13*$T$3 -> 4.458349
B14: 201912 | C14: 2.77 | D14: 0.73 | E14: 1.78 | F14: 0.14 | G14: 2.6916287 | H14: 5.0616661 | I14: 16.999205 | J14: 1.1633979 | K14: 2.4517515 | L14: 6.6900526 | V14: =C14*$N$3+G14*$O$3+H14*$P$3+I14*$Q$3+J14*$R$3+K14*$S$3+L14*$T$3 -> 4.9328144
B15: 202001 | C15: -0.11 | D15: -3.13 | E15: -6.25 | F15: 0.13 | G15: 6.5207984 | H15: -7.0046668 | I15: 2.3558242 | J15: -11.530996 | K15: -11.710193 | L15: 1.9265852 | V15: =C15*$N$3+G15*$O$3+H15*$P$3+I15*$Q$3+J15*$R$3+K15*$S$3+L15*$T$3 -> -2.1217555
... B62: 202312 | C62: 4.87 | D62: 6.36 | E62: 4.92 | F62: 0.43 | G62: 2.2938019 | H62: -1.1964162 | I62: 21.235565 | J62: 8.7600115 | K62: -0.43 | L62: 1.7264679 | V62: =C62*$N$3+G62*$O$3+H62*$P$3+I62*$Q$3+J62*$R$3+K62*$S$3+L62*$T$3 -> 4.4528112
B69: SUMMARY OUTPUT | D69: (Active Portfolio)
B71: Regression Statistics
B72: Multiple R | C72: 0.90534265
B73: R Square | C73: 0.81964532
B74: Adjusted R Square | C74: 0.80998346
B75: Standard Error | C75: 2.5373564
B76: Observations | C76: 60
B78: ANOVA
C79: df | D79: SS | E79: MS | F79: F | G79: Significance F
B80: Regression | C80: 3 | D80: 1638.5116 | E80: 546.17053 | F80: 84.833097 | G80: 8.1620889e-21
B81: Residual | C81: 56 | D81: 360.53793 | E81: 6.4381774
B82: Total | C82: 59 | D82: 1999.0495
C84: Coefficients | D84: Standard Error | E84: t Stat | F84: P-value | G84: Lower 95% | H84: Upper 95% | I84: Lower 95.0% | J84: Upper 95.0%
B85: Intercept | C85: 0.53619003 | D85: 0.3365173 | E85: 1.5933506 | F85: 0.11671088 | G85: -0.13793513 | H85: 1.2103152 | I85: -0.13793513 | J85: 1.2103152
B86: Excess Market | C86: 0.92275952 | D86: 0.063050525 | E86: 14.635239 | F86: 8.6480885e-21 | G86: 0.79645414 | H86: 1.0490649 | I86: 0.79645414 | J86: 1.0490649
B87: SMB | C87: 0.14007223 | D87: 0.12019881 | E87: 1.1653379 | F87: 0.24882207 | G87: -0.10071492 | H87: 0.38085938 | I87: -0.10071492 | J87: 0.38085938
B88: HML | C88: -0.059308002 | D88: 0.070275493 | E88: -0.84393577 | F88: 0.40229607 | G88: -0.20008673 | H88: 0.081470727 | I88: -0.20008673 | J88: 0.081470727
B91: Comments
B93: Both SMB and HML have high P-value for the null hypothesis that both equal to zero, so we fail to reject the null
B95: In other words, both SMB and HML are neutral | F95: so, the result in problem 10 is " mid-balance"
B97: This active portfolio has beta less than 1

Sheet ETF QQQ
C1: Open | D1: High | E1: Low | F1: Close | G1: Adj Close
B2: Date
B3: 43435 | C3: 173.11 | D3: 173.31 | E3: 143.46001 | F3: 154.26 | G3: 148.1982 | I3: Monthly Return
B4: 43466 | C4: 150.99 | D4: 168.99 | E4: 149.49 | F4: 168.16 | G4: 162.01416 | H4: =G4/G3-1 -> 0.093226263 | I4: =H4*100 -> 9.3226263
B5: 43497 | C5: 167.33 | D5: 174.66 | E5: 166.57001 | F5: 173.19 | G5: 166.86032 | H5: =G5/G4-1 -> 0.02991196 | I5: =H5*100 -> 2.991196
B6: 43525 | C6: 174.44 | D6: 182.83 | E6: 169.34 | F6: 179.66 | G6: 173.09387 | H6: =G6/G5-1 -> 0.037357899 | I6: =H6*100 -> 3.7357899
B7: 43556 | C7: 181.51 | D7: 191.32001 | E7: 180.77 | F7: 189.53999 | G7: 182.94508 | H7: =G7/G6-1 -> 0.05691254 | I7: =H7*100 -> 5.691254
B8: 43586 | C8: 190.78 | D8: 191.32001 | E8: 173.86999 | F8: 173.95 | G8: 167.89757 | H8: =G8/G7-1 -> -0.082251546 | I8: =H8*100 -> -8.2251546
B9: 43617 | C9: 173.48 | D9: 189.77 | E9: 169.27 | F9: 186.74 | G9: 180.24254 | H9: =G9/G8-1 -> 0.073526795 | I9: =H9*100 -> 7.3526795
B10: 43647 | C10: 190.32001 | D10: 195.55 | E10: 188.38001 | F10: 191.10001 | G10: 184.85866 | H10: =G10/G9-1 -> 0.025610603 | I10: =H10*100 -> 2.5610603
B11: 43678 | C11: 191.42999 | D11: 194.98 | E11: 179.2 | F11: 187.47 | G11: 181.34717 | H11: =G11/G10-1 -> -0.01899554 | I11: =H11*100 -> -1.899554
B12: 43709 | C12: 186.22 | D12: 194.71001 | E12: 185.03 | F12: 188.81 | G12: 182.64345 | H12: =G12/G11-1 -> 0.0071480576 | I12: =H12*100 -> 0.71480576
B13: 43739 | C13: 189.5 | D13: 197.83 | E13: 181.82001 | F13: 197.08 | G13: 191.02779 | H13: =G13/G12-1 -> 0.045905496 | I13: =H13*100 -> 4.5905496
B14: 43770 | C14: 197.92999 | D14: 206.05 | E14: 197.63001 | F14: 205.10001 | G14: 198.8015 | H14: =G14/G13-1 -> 0.040694143 | I14: =H14*100 -> 4.0694143
B15: 43800 | C15: 205.11 | D15: 214.56 | E15: 199.23 | F15: 212.61 | G15: 206.08089 | H15: =G15/G14-1 -> 0.036616369 | I15: =H15*100 -> 3.6616369
... B63: 45261 | C63: 387.75 | D63: 412.92001 | E63: 382.66 | F63: 409.51999 | G63: 406.73041 | H63: =G63/G62-1 -> 0.053210858 | I63: =H63*100 -> 5.3210858

Sheet Visualization
N3: BMK beta | O3: =SLOPE(F6:F65,E6:E65) -> 0.79149544
B4: Date | C4: Risk-Free (%) | D4: ETF Return (%) | E4: ETF Excess Return (%) | F4: Active Portfolio Excess Return (%) | G4: Active Portfolio Return (%) | H4: Benchmark Return (%) | I4: BMK Equity Curve | J4: Portfolio Equity Curve
I5: 1 | J5: 1
B6: 201901 | C6: ='CAPM Regression'!P4 -> 0.21 | D6: ='ETF QQQ'!I4 -> 9.3226263 | E6: =D6-C6 -> 9.1126263 | F6: ='SMB+HML'!V3 -> 13.441238 | G6: =C6+F6 -> 13.651238 | H6: =(1-$O$3)*C6+$O$3*D6 -> 7.4226022 | I6: =I5*(1+H6/100) -> 1.074226 | J6: =J5*(1+G6/100) -> 1.1365124
B7: 201902 | C7: ='CAPM Regression'!P5 -> 0.18 | D7: ='ETF QQQ'!I5 -> 2.991196 | E7: =D7-C7 -> 2.811196 | F7: ='SMB+HML'!V4 -> 2.2162381 | G7: =C7+F7 -> 2.3962381 | H7: =(1-$O$3)*C7+$O$3*D7 -> 2.4050488 | I7: =I6*(1+H7/100) -> 1.1000617 | J7: =J6*(1+G7/100) -> 1.1637459
B8: 201903 | C8: ='CAPM Regression'!P6 -> 0.19 | D8: ='ETF QQQ'!I6 -> 3.7357899 | E8: =D8-C8 -> 3.5457899 | F8: ='SMB+HML'!V5 -> 0.9599096 | G8: =C8+F8 -> 1.1499096 | H8: =(1-$O$3)*C8+$O$3*D8 -> 2.9964765 | I8: =I7*(1+H8/100) -> 1.1330248 | J8: =J7*(1+G8/100) -> 1.1771279
B9: 201904 | C9: ='CAPM Regression'!P7 -> 0.21 | D9: ='ETF QQQ'!I7 -> 5.691254 | E9: =D9-C9 -> 5.481254 | F9: ='SMB+HML'!V6 -> 3.7062079 | G9: =C9+F9 -> 3.9162079 | H9: =(1-$O$3)*C9+$O$3*D9 -> 4.5483876 | I9: =I8*(1+H9/100) -> 1.1845591 | J9: =J8*(1+G9/100) -> 1.2232267
B10: 201905 | C10: ='CAPM Regression'!P8 -> 0.21 | D10: ='ETF QQQ'!I8 -> -8.2251546 | E10: =D10-C10 -> -8.4351546 | F10: ='SMB+HML'!V7 -> -5.928891 | G10: =C10+F10 -> -5.718891 | H10: =(1-$O$3)*C10+$O$3*D10 -> -6.4663864 | I10: =I9*(1+H10/100) -> 1.107961 | J10: =J9*(1+G10/100) -> 1.1532717
B11: 201906 | C11: ='CAPM Regression'!P9 -> 0.18 | D11: ='ETF QQQ'!I9 -> 7.3526795 | E11: =D11-C11 -> 7.1726795 | F11: ='SMB+HML'!V8 -> 7.4631186 | G11: =C11+F11 -> 7.6431186 | H11: =(1-$O$3)*C11+$O$3*D11 -> 5.8571431 | I11: =I10*(1+H11/100) -> 1.1728558 | J11: =J10*(1+G11/100) -> 1.2414176
B12: 201907 | C12: ='CAPM Regression'!P10 -> 0.19 | D12: ='ETF QQQ'!I10 -> 2.5610603 | E12: =D12-C12 -> 2.3710603 | F12: ='SMB+HML'!V9 -> -3.6780535 | G12: =C12+F12 -> -3.4880535 | H12: =(1-$O$3)*C12+$O$3*D12 -> 2.0666834 | I12: =I11*(1+H12/100) -> 1.197095 | J12: =J11*(1+G12/100) -> 1.1981163
B13: 201908 | C13: ='CAPM Regression'!P11 -> 0.16 | D13: ='ETF QQQ'!I11 -> -1.899554 | E13: =D13-C13 -> -2.059554 | F13: ='SMB+HML'!V10 -> -2.5249948 | G13: =C13+F13 -> -2.3649948 | H13: =(1-$O$3)*C13+$O$3*D13 -> -1.4701276 | I13: =I12*(1+H13/100) -> 1.1794962 | J13: =J12*(1+G13/100) -> 1.1697809
B14: 201909 | C14: ='CAPM Regression'!P12 -> 0.18 | D14: ='ETF QQQ'!I12 -> 0.71480576 | E14: =D14-C14 -> 0.53480576 | F14: ='SMB+HML'!V11 -> -1.1618515 | G14: =C14+F14 -> -0.98185147 | H14: =(1-$O$3)*C14+$O$3*D14 -> 0.60329632 | I14: =I13*(1+H14/100) -> 1.1866121 | J14: =J13*(1+G14/100) -> 1.1582954
B15: 201910 | C15: ='CAPM Regression'!P13 -> 0.16 | D15: ='ETF QQQ'!I13 -> 4.5905496 | E15: =D15-C15 -> 4.4305496 | F15: ='SMB+HML'!V12 -> 3.1778299 | G15: =C15+F15 -> 3.3378299 | H15: =(1-$O$3)*C15+$O$3*D15 -> 3.6667598 | I15: =I14*(1+H15/100) -> 1.2301223 | J15: =J14*(1+G15/100) -> 1.1969574
B16: 201911 | C16: ='CAPM Regression'!P14 -> 0.12 | D16: ='ETF QQQ'!I14 -> 4.0694143 | E16: =D16-C16 -> 3.9494143 | F16: ='SMB+HML'!V13 -> 4.458349 | G16: =C16+F16 -> 4.578349 | H16: =(1-$O$3)*C16+$O$3*D16 -> 3.2459434 | I16: =I15*(1+H16/100) -> 1.2700514 | J16: =J15*(1+G16/100) -> 1.2517583
B17: 201912 | C17: ='CAPM Regression'!P15 -> 0.14 | D17: ='ETF QQQ'!I15 -> 3.6616369 | E17: =D17-C17 -> 3.5216369 | F17: ='SMB+HML'!V14 -> 4.9328144 | G17: =C17+F17 -> 5.0728144 | H17: =(1-$O$3)*C17+$O$3*D17 -> 2.9273595 | I17: =I16*(1+H17/100) -> 1.3072303 | J17: =J16*(1+G17/100) -> 1.3152576
... B65: 202312 | C65: ='CAPM Regression'!P63 -> 0.43 | D65: ='ETF QQQ'!I63 -> 5.3210858 | E65: =D65-C65 -> 4.8910858 | F65: ='SMB+HML'!V62 -> 4.4528112 | G65: =C65+F65 -> 4.8828112 | H65: =(1-$O$3)*C65+$O$3*D65 -> 4.3012721 | I65: =I64*(1+H65/100) -> 2.3126739 | J65: =J64*(1+G65/100) -> 2.6035295
F67: 22-23 Return | G67: =AVERAGE(G54:G65) -> 2.4128828

Sheet Investment Style
G26: Value | H26: Balance | I26: Growth
D27: Investment Style | F27: Large
F28: Mid
F29: Small
D32: Investment Objective | F32: To help clients to earn the profit as large as possible, while minimizing the risks as much as possible
D35: ETF Style | F35: neutral to moderately defensive
D38: Active Portfolio Analysis
F40: Sector | G40: Beta | H40: Predicted Alpha | I40: 22-23 Overall Return | J40: Weight in Active Portfolio | K40: Variance | L40: Position Trend
E41: Netflix | F41: Communication | G41: ='Active Porfolio'!G11 -> 1.2757874 | H41: ='Active Porfolio'!F11 -> 0.56819191 | I41: ='P2 Netflix'!G65 -> 0.65111231 | J41: ='Active Porfolio'!D38 -> 0.14259114 | K41: ='Active Porfolio'!I11 -> 98.135623 | L41: (-)
E42: PDD | F42: E-Commerce | G42: ='Active Porfolio'!G12 -> 0.86510832 | H42: ='Active Porfolio'!F12 -> 0.67984665 | I42: ='P2 PDD'!G66 -> 0.66773046 | J42: ='Active Porfolio'!D39 -> 0.042377682 | K42: ='Active Porfolio'!I12 -> 395.09174 | L42: (-)
E43: AMD | F43: IT | G43: ='Active Porfolio'!G13 -> 1.6319119 | H43: ='Active Porfolio'!F13 -> 0.61618443 | I43: ='P2 AMD'!G66 -> 1.2758995 | J43: ='Active Porfolio'!D40 -> 0.095818707 | K43: ='Active Porfolio'!I13 -> 158.37426 | L43: (-)
E44: FSLR | F44: Technology | G44: ='Active Porfolio'!G14 -> 1.4570306 | H44: ='Active Porfolio'!F14 -> 0.62341874 | I44: ='P2 FSLR'!G65 -> 0.15014358 | J44: ='Active Porfolio'!D41 -> 0.10340218 | K44: ='Active Porfolio'!I14 -> 148.48218 | L44: (+)
E45: Shell | F45: Energy | G45: ='Active Porfolio'!G15 -> 0.61824725 | H45: ='Active Porfolio'!F15 -> 0.44737701 | I45: ='P2 Shell'!G65 -> 0.15539951 | J45: ='Active Porfolio'!D42 -> 0.19041355 | K45: ='Active Porfolio'!I15 -> 57.862874 | L45: (+)
E46: JNJ | F46: Healthcare | G46: ='Active Porfolio'!G16 -> 0.48048942 | H46: ='Active Porfolio'!F16 -> 0.18562004 | I46: ='P2 JNJ'!H65 -> -0.085783813 | J46: ='Active Porfolio'!D43 -> 0.23983732 | K46: ='Active Porfolio'!I16 -> 19.060412 | L46: (+)
E47: Market Portfolio | F47: Market-Risk-Free | G47: 1 | H47: / | I47: / | J47: ='SMB+HML'!N3 -> 0.18555942 | K47: ='CAPM Regression'!O68 -> 30.910951 | L47: (-)
D50: Financial Ratios
E52: Revenue (2023) | F52: Asset (2023) | G52: EPS (2023) | H52: EBITDA (2023) | I52: lastest P/E | J52: Current Ratio | K52: ROE (2024/06/30)
D53: Netflix | E53: $ 33.723 billion | F53: $ 48.732 billion | G53: 12.03 | H53: 21.508 billion | I53: 44.56 | J53: 0.95 | K53: 0.3293
D55: PDD | E55: $13.356 billion | F55: $490.026 billion | G55: 5.81 | H55: 4.481 billion | I55: 14.66 | J55: 2.11 | K55: 0.4832
D57: AMD | E57: $ 22.68 billion | F57: $67.885 billion | G57: 0.53 | H57: 3.955 billion | I57: 80.62 | J57: 2.82 | K57: 0.0242
D59: FSLR | E59: $3.319 billion | F59: $10.365 billion | G59: 7.74 | H59: 1.165 billion | I59: 18.75 | J59: 2.23 | K59: 0.1773
D61: Shell | E61: $323.183 billion | F61: $ 406.27 billion | G61: 5.7 | H61: 68.59 billion | I61: 8.11 | J61: 1.41 | K61: 0.0972
D63: JNJ | E63: $ 85.159 billion | F63: $ 167.558 billion | G63: 13.72 | H63: 24.581 billion | I63: 15.42 | J63: 1.07 | K63: 0.5401
D68: Active Portfolio's Data | F68: Beta | G68: ='Active Porfolio'!D47 -> 0.94412646
F69: Variance | G69: ='Active Porfolio'!D49 -> 9.8322111
F70: Sharpe Ratio | G70: ='Active Porfolio'!D51 -> 0.47257704
